Workbook

Sheet Summary
A1: Section | B1: Tests | C1: Pass | D1: Fail | E1: Blocked | F1: N/A | G1: Not run | H1: % done
A2: 00 Setup & smoke | B2: =COUNTIF(Tests!$B:$B,$A2) -> 9 | C2: =COUNTIFS(Tests!$B:$B,$A2,Tests!$H:$H,"Pass") -> 0 | D2: =COUNTIFS(Tests!$B:$B,$A2,Tests!$H:$H,"Fail") -> 0 | E2: =COUNTIFS(Tests!$B:$B,$A2,Tests!$H:$H,"Blocked") -> 0 | F2: =COUNTIFS(Tests!$B:$B,$A2,Tests!$H:$H,"N/A") -> 0 | G2: =COUNTIFS(Tests!$B:$B,$A2,Tests!$H:$H,"Not run") -> 9 | H2: =IF(B2=0,0,(B2-G2)/B2) -> 0
A3: 01 Registration | B3: =COUNTIF(Tests!$B:$B,$A3) -> 20 | C3: =COUNTIFS(Tests!$B:$B,$A3,Tests!$H:$H,"Pass") -> 0 | D3: =COUNTIFS(Tests!$B:$B,$A3,Tests!$H:$H,"Fail") -> 0 | E3: =COUNTIFS(Tests!$B:$B,$A3,Tests!$H:$H,"Blocked") -> 0 | F3: =COUNTIFS(Tests!$B:$B,$A3,Tests!$H:$H,"N/A") -> 0 | G3: =COUNTIFS(Tests!$B:$B,$A3,Tests!$H:$H,"Not run") -> 20 | H3: =IF(B3=0,0,(B3-G3)/B3) -> 0
A4: 02 Login & security | B4: =COUNTIF(Tests!$B:$B,$A4) -> 24 | C4: =COUNTIFS(Tests!$B:$B,$A4,Tests!$H:$H,"Pass") -> 0 | D4: =COUNTIFS(Tests!$B:$B,$A4,Tests!$H:$H,"Fail") -> 0 | E4: =COUNTIFS(Tests!$B:$B,$A4,Tests!$H:$H,"Blocked") -> 0 | F4: =COUNTIFS(Tests!$B:$B,$A4,Tests!$H:$H,"N/A") -> 0 | G4: =COUNTIFS(Tests!$B:$B,$A4,Tests!$H:$H,"Not run") -> 24 | H4: =IF(B4=0,0,(B4-G4)/B4) -> 0
A5: 03 Shop browsing & filters | B5: =COUNTIF(Tests!$B:$B,$A5) -> 38 | C5: =COUNTIFS(Tests!$B:$B,$A5,Tests!$H:$H,"Pass") -> 0 | D5: =COUNTIFS(Tests!$B:$B,$A5,Tests!$H:$H,"Fail") -> 0 | E5: =COUNTIFS(Tests!$B:$B,$A5,Tests!$H:$H,"Blocked") -> 0 | F5: =COUNTIFS(Tests!$B:$B,$A5,Tests!$H:$H,"N/A") -> 0 | G5: =COUNTIFS(Tests!$B:$B,$A5,Tests!$H:$H,"Not run") -> 38 | H5: =IF(B5=0,0,(B5-G5)/B5) -> 0
A6: 04 Cart | B6: =COUNTIF(Tests!$B:$B,$A6) -> 10 | C6: =COUNTIFS(Tests!$B:$B,$A6,Tests!$H:$H,"Pass") -> 0 | D6: =COUNTIFS(Tests!$B:$B,$A6,Tests!$H:$H,"Fail") -> 0 | E6: =COUNTIFS(Tests!$B:$B,$A6,Tests!$H:$H,"Blocked") -> 0 | F6: =COUNTIFS(Tests!$B:$B,$A6,Tests!$H:$H,"N/A") -> 0 | G6: =COUNTIFS(Tests!$B:$B,$A6,Tests!$H:$H,"Not run") -> 10 | H6: =IF(B6=0,0,(B6-G6)/B6) -> 0
A7: 05 Checkout | B7: =COUNTIF(Tests!$B:$B,$A7) -> 13 | C7: =COUNTIFS(Tests!$B:$B,$A7,Tests!$H:$H,"Pass") -> 0 | D7: =COUNTIFS(Tests!$B:$B,$A7,Tests!$H:$H,"Fail") -> 0 | E7: =COUNTIFS(Tests!$B:$B,$A7,Tests!$H:$H,"Blocked") -> 0 | F7: =COUNTIFS(Tests!$B:$B,$A7,Tests!$H:$H,"N/A") -> 0 | G7: =COUNTIFS(Tests!$B:$B,$A7,Tests!$H:$H,"Not run") -> 13 | H7: =IF(B7=0,0,(B7-G7)/B7) -> 0
A8: 06 Payment & placing orders | B8: =COUNTIF(Tests!$B:$B,$A8) -> 13 | C8: =COUNTIFS(Tests!$B:$B,$A8,Tests!$H:$H,"Pass") -> 0 | D8: =COUNTIFS(Tests!$B:$B,$A8,Tests!$H:$H,"Fail") -> 0 | E8: =COUNTIFS(Tests!$B:$B,$A8,Tests!$H:$H,"Blocked") -> 0 | F8: =COUNTIFS(Tests!$B:$B,$A8,Tests!$H:$H,"N/A") -> 0 | G8: =COUNTIFS(Tests!$B:$B,$A8,Tests!$H:$H,"Not run") -> 13 | H8: =IF(B8=0,0,(B8-G8)/B8) -> 0
A9: 07 My Orders | B9: =COUNTIF(Tests!$B:$B,$A9) -> 16 | C9: =COUNTIFS(Tests!$B:$B,$A9,Tests!$H:$H,"Pass") -> 0 | D9: =COUNTIFS(Tests!$B:$B,$A9,Tests!$H:$H,"Fail") -> 0 | E9: =COUNTIFS(Tests!$B:$B,$A9,Tests!$H:$H,"Blocked") -> 0 | F9: =COUNTIFS(Tests!$B:$B,$A9,Tests!$H:$H,"N/A") -> 0 | G9: =COUNTIFS(Tests!$B:$B,$A9,Tests!$H:$H,"Not run") -> 16 | H9: =IF(B9=0,0,(B9-G9)/B9) -> 0
A10: 08 Account settings | B10: =COUNTIF(Tests!$B:$B,$A10) -> 11 | C10: =COUNTIFS(Tests!$B:$B,$A10,Tests!$H:$H,"Pass") -> 0 | D10: =COUNTIFS(Tests!$B:$B,$A10,Tests!$H:$H,"Fail") -> 0 | E10: =COUNTIFS(Tests!$B:$B,$A10,Tests!$H:$H,"Blocked") -> 0 | F10: =COUNTIFS(Tests!$B:$B,$A10,Tests!$H:$H,"N/A") -> 0 | G10: =COUNTIFS(Tests!$B:$B,$A10,Tests!$H:$H,"Not run") -> 11 | H10: =IF(B10=0,0,(B10-G10)/B10) -> 0
A11: 09 Live chat (shop) | B11: =COUNTIF(Tests!$B:$B,$A11) -> 12 | C11: =COUNTIFS(Tests!$B:$B,$A11,Tests!$H:$H,"Pass") -> 0 | D11: =COUNTIFS(Tests!$B:$B,$A11,Tests!$H:$H,"Fail") -> 0 | E11: =COUNTIFS(Tests!$B:$B,$A11,Tests!$H:$H,"Blocked") -> 0 | F11: =COUNTIFS(Tests!$B:$B,$A11,Tests!$H:$H,"N/A") -> 0 | G11: =COUNTIFS(Tests!$B:$B,$A11,Tests!$H:$H,"Not run") -> 12 | H11: =IF(B11=0,0,(B11-G11)/B11) -> 0
A12: 10 Role access | B12: =COUNTIF(Tests!$B:$B,$A12) -> 8 | C12: =COUNTIFS(Tests!$B:$B,$A12,Tests!$H:$H,"Pass") -> 0 | D12: =COUNTIFS(Tests!$B:$B,$A12,Tests!$H:$H,"Fail") -> 0 | E12: =COUNTIFS(Tests!$B:$B,$A12,Tests!$H:$H,"Blocked") -> 0 | F12: =COUNTIFS(Tests!$B:$B,$A12,Tests!$H:$H,"N/A") -> 0 | G12: =COUNTIFS(Tests!$B:$B,$A12,Tests!$H:$H,"Not run") -> 8 | H12: =IF(B12=0,0,(B12-G12)/B12) -> 0
A13: 11 Dashboard | B13: =COUNTIF(Tests!$B:$B,$A13) -> 15 | C13: =COUNTIFS(Tests!$B:$B,$A13,Tests!$H:$H,"Pass") -> 0 | D13: =COUNTIFS(Tests!$B:$B,$A13,Tests!$H:$H,"Fail") -> 0 | E13: =COUNTIFS(Tests!$B:$B,$A13,Tests!$H:$H,"Blocked") -> 0 | F13: =COUNTIFS(Tests!$B:$B,$A13,Tests!$H:$H,"N/A") -> 0 | G13: =COUNTIFS(Tests!$B:$B,$A13,Tests!$H:$H,"Not run") -> 15 | H13: =IF(B13=0,0,(B13-G13)/B13) -> 0
... A36: 34 End-to-end scenarios | B36: =COUNTIF(Tests!$B:$B,$A36) -> 8 | C36: =COUNTIFS(Tests!$B:$B,$A36,Tests!$H:$H,"Pass") -> 0 | D36: =COUNTIFS(Tests!$B:$B,$A36,Tests!$H:$H,"Fail") -> 0 | E36: =COUNTIFS(Tests!$B:$B,$A36,Tests!$H:$H,"Blocked") -> 0 | F36: =COUNTIFS(Tests!$B:$B,$A36,Tests!$H:$H,"N/A") -> 0 | G36: =COUNTIFS(Tests!$B:$B,$A36,Tests!$H:$H,"Not run") -> 8 | H36: =IF(B36=0,0,(B36-G36)/B36) -> 0
A37: Total | B37: =SUM(B2:B36) -> 469 | C37: =SUM(C2:C36) -> 0 | D37: =SUM(D2:D36) -> 0 | E37: =SUM(E2:E36) -> 0 | F37: =SUM(F2:F36) -> 0 | G37: =SUM(G2:G36) -> 469 | H37: =IF(B37=0,0,(B37-G37)/B37) -> 0
A38: Role Access cells | B38: =COUNTA('Role Access'!G2:K29) -> 140 | C38: =COUNTIF('Role Access'!G2:K29,"Pass") -> 0 | D38: =COUNTIF('Role Access'!G2:K29,"Fail") -> 0 | E38: =COUNTIF('Role Access'!G2:K29,"Blocked") -> 0 | F38: =COUNTIF('Role Access'!G2:K29,"N/A") -> 0 | G38: =COUNTIF('Role Access'!G2:K29,"Not run") -> 140 | H38: =IF(B38=0,0,(B38-G38)/B38) -> 0

Sheet Read Me
A1: AMSON - Full System Test Plan
A2: Covers every page, button, filter, tab, sort, search, export, role and business rule in the webapp branch (rules commit 7fdbde9 live on amson-web-app).
A4: How to use
A5: 1. Run on the deployed site (or http://localhost:8080 while Netlify is pending). Use a fresh browser profile per role.
A6: 2. Set Result for each row: Pass / Fail / Blocked / N/A. Leave 'Not run' until tested. On Fail, write what happened in Notes (and add a To-Do row in the Deviation Register).
A7: 3. Do the 'Role Access' sheet once per role. The Summary sheet counts results by section.
A8: 4. Run sections in order: 00 Setup first, 34 End-to-end last. Sections 13-15 and 17-22 need orders and stock created by earlier sections.
A10: Accounts needed (each with a real inbox, because device codes and order emails are sent)
A11: - 2 customers (A, B) - B is used for 'another customer's order' and cart-isolation tests
A12: - 1 Branch Manager, 1 Technical Staff, 1 Sales Staff (create the last two in Staff Management, test 26)
A13: - 1 spare customer and 1 spare staff account to deactivate
A15: Test data needed
... A27: Before go-live: clear test data (test 31) and set REQUIRE_DEVICE_CODE back to true (test 00).

Sheet Tests
A1: ID | B1: Section | C1: Page / where | D1: Log in as | E1: Steps | F1: Expected result | G1: Req | H1: Result | I1: Tester | J1: Date | K1: Notes / bug
A2: T00-01 | B2: 00 Setup & smoke | C2: Site URL | D2: Guest | E2: Open the hosted site (Netlify URL) over https://. | F2: Loads with a padlock (HTTPS); no browser security warning. | G2: REQNF010 | H2: Not run
A3: T00-02 | B3: 00 Setup & smoke | C3: Site URL | D3: Guest | E3: Open index.html. | F3: Redirects to shop/index.html. | H3: Not run
A4: T00-03 | B4: 00 Setup & smoke | C4: Any page | D4: Guest | E4: Open DevTools > Console on the shop home page and reload. | F4: No red errors (Firebase, Cloudinary, EmailJS, Chart.js, jsPDF load). | H4: Not run
A5: T00-04 | B5: 00 Setup & smoke | C5: Any page | D5: Guest | E5: Deploy a small change, then reload normally (no hard refresh). | F5: New version shows (_headers no-cache works). | H5: Not run
A6: T00-05 | B6: 00 Setup & smoke | C6: Firebase console | D6: Branch Manager | E6: Firestore > Rules: compare with firestore.rules on webapp. | F6: Published rules are the latest commit. | G6: REQNF011 | H6: Not run
A7: T00-06 | B7: 00 Setup & smoke | C7: Firebase console | D7: Branch Manager | E7: Authentication > Settings > Authorized domains. | F7: Netlify domain is listed (otherwise login fails on the hosted site). | H7: Not run
A8: T00-07 | B8: 00 Setup & smoke | C8: js/device-trust.js | D8: Branch Manager | E8: Confirm REQUIRE_DEVICE_CODE is true for go-live (false only while testing with fake inboxes). | F8: true on the deployed site. | G8: REQ005 | H8: Not run
A9: T00-08 | B9: 00 Setup & smoke | C9: assets/payment-qr.png | D9: Guest | E9: Open shop/payment.html with an item in the cart. | F9: The branch's real QR Ph image shows (not a placeholder). | G9: REQ028 | H9: Not run
A10: T00-09 | B10: 00 Setup & smoke | C10: js/store-info.js | D10: Guest | E10: Scroll to the footer on any page. | F10: Real store name, address, contact numbers and FDA LTO no. | H10: Not run
A11: T01-01 | B11: 01 Registration | C11: register.html | D11: Guest | E11: Submit with every field empty. | F11: Each required field shows an error; nothing is created. | G11: REQ001 | H11: Not run
A12: T01-02 | B12: 01 Registration | C12: register.html | D12: Guest | E12: First/last name with digits or symbols (e.g. 'Juan2', 'Dela@Cruz'). | F12: Rejected with a name-format message. | G12: REQ001 | H12: Not run
A13: T01-03 | B13: 01 Registration | C13: register.html | D13: Guest | E13: Names with accents, hyphen, period/space (e.g. 'José', 'Dela-Cruz', 'Ma. Clara'). | F13: Accepted. | G13: REQ001 | H13: Not run
A14: T01-04 | B14: 01 Registration | C14: register.html | D14: Guest | E14: Invalid email (e.g. 'juan@', 'juan@gmail', '.juan@gmail.com'). | F14: Rejected. | G14: REQ001 | H14: Not run
A15: T01-05 | B15: 01 Registration | C15: register.html | D15: Guest | E15: Disposable email domain (e.g. @mailnesia.com, @getnada.com). | F15: Rejected as a temporary email. | G15: REQ001 | H15: Not run
A16: T01-06 | B16: 01 Registration | C16: register.html | D16: Guest | E16: Contact no. '0917123456' (10 digits), '+6391712345678', '08171234567'. | F16: Rejected; only 09XXXXXXXXX or +639XXXXXXXXX accepted. | G16: REQ001 | H16: Not run
A17: T01-07 | B17: 01 Registration | C17: register.html | D17: Guest | E17: Contact no. '09171234567' and '+639171234567'. | F17: Both accepted. | G17: REQ001 | H17: Not run
A18: T01-08 | B18: 01 Registration | C18: register.html | D18: Guest | E18: Password 'abcdef', '123456', 'abc123' (no symbol), 'a1!' (too short). | F18: Each rejected: needs 6+ chars with a letter, a digit and a symbol. | G18: REQ001 | H18: Not run
A19: T01-09 | B19: 01 Registration | C19: register.html | D19: Guest | E19: Password 'abc12!' with a different Confirm Password. | F19: Rejected: passwords don't match. | G19: REQ001 | H19: Not run
A20: T01-10 | B20: 01 Registration | C20: register.html | D20: Guest | E20: Click the eye icon on both password fields. | F20: Toggles show/hide. | H20: Not run
A21: T01-11 | B21: 01 Registration | C21: register.html | D21: Guest | E21: Submit without ticking 'I agree' to the Terms. | F21: Blocked with a message. | G21: REQ006 | H21: Not run
A22: T01-12 | B22: 01 Registration | C22: register.html | D22: Guest | E22: Open the Terms link, read, click 'I Have Read and Agree'; also try Close. | F22: Agree ticks the box; Close leaves it unticked. | G22: REQ006 | H22: Not run
A23: T01-13 | B23: 01 Registration | C23: register.html | D23: Guest | E23: Submit without completing reCAPTCHA. | F23: 'Please complete the reCAPTCHA verification.' | G23: REQ003 | H23: Not run
A24: T01-14 | B24: 01 Registration | C24: register.html | D24: Guest | E24: Register with an email that already has an account. | F24: Clear 'already registered' message; no duplicate. | G24: REQ001 | H24: Not run
A25: T01-15 | B25: 01 Registration | C25: register.html | D25: Guest | E25: Register with valid data and a real inbox. | F25: Goes to verify-email.html; 6-digit code arrives by email. | G25: REQ002 | H25: Not run
A26: T01-16 | B26: 01 Registration | C26: verify-email.html | D26: Customer | E26: Type a wrong 6-digit code. | F26: Rejected; account stays unverified. | G26: REQ002 | H26: Not run
A27: T01-17 | B27: 01 Registration | C27: verify-email.html | D27: Customer | E27: Paste the code; also type digit by digit (auto-advance between the 6 boxes). | F27: Both work; correct code verifies and continues. | G27: REQ002 | H27: Not run
A28: T01-18 | B28: 01 Registration | C28: verify-email.html | D28: Customer | E28: Click 'Wrong email? Go back to registration'. | F28: Returns to registration. | H28: Not run
A29: T01-19 | B29: 01 Registration | C29: verify-email.html | D29: Customer | E29: Wait past expiry / request resend (if shown), then use the old code. | F29: Old code rejected; new code works. | G29: REQ002 | H29: Not run
A30: T01-20 | B30: 01 Registration | C30: login.html | D30: Customer | E30: Log in with a registered but unverified account. | F30: Sent to email verification, not into the shop. | G30: REQ002 | H30: Not run
A31: T02-01 | B31: 02 Login & security | C31: login.html | D31: Customer | E31: Log in with correct customer credentials (recognized device). | F31: Lands on the shop as signed in; header shows Account. | G31: REQ043 | H31: Not run
A32: T02-02 | B32: 02 Login & security | C32: login.html | D32: Sales Staff | E32: Log in as Sales Staff. | F32: Lands on admin/pos.html. | G32: REQ121 | H32: Not run
A33: T02-03 | B33: 02 Login & security | C33: login.html | D33: Technical Staff | E33: Log in as Technical Staff. | F33: Lands on admin/dashboard.html. | G33: REQ043 | H33: Not run
A34: T02-04 | B34: 02 Login & security | C34: login.html | D34: Branch Manager | E34: Log in as Branch Manager. | F34: Lands on admin/dashboard.html. | G34: REQ043 | H34: Not run
A35: T02-05 | B35: 02 Login & security | C35: login.html | D35: Guest | E35: Wrong password once. | F35: Generic error; no hint whether the email exists. | H35: Not run
A36: T02-06 | B36: 02 Login & security | C36: login.html | D36: Guest | E36: Wrong password 5 times in a row for the same email. | F36: Account locked for 2 minutes with a countdown/message. | G36: REQ004 | H36: Not run
A37: T02-07 | B37: 02 Login & security | C37: login.html | D37: Guest | E37: During the lock, try the correct password. | F37: Still refused until 2 minutes pass. | G37: REQ004 | H37: Not run
A38: T02-08 | B38: 02 Login & security | C38: login.html | D38: Guest | E38: After 2 minutes, log in with the correct password. | F38: Works; counter resets. | G38: REQ004 | H38: Not run
A39: T02-09 | B39: 02 Login & security | C39: login.html | D39: Branch Manager | E39: Lockout for staff: 5 wrong passwords on a staff email. | F39: Locked for 2 minutes, same as customers. | G39: REQ045 | H39: Not run
A40: T02-10 | B40: 02 Login & security | C40: login.html | D40: Guest | E40: Submit without reCAPTCHA. | F40: Blocked. | G40: REQ003 | H40: Not run
...

Sheet Role Access
A1: Page | B1: Expected: Guest | C1: Expected: Customer | D1: Expected: Sales Staff | E1: Expected: Technical Staff | F1: Expected: Branch Manager | G1: Result: Guest | H1: Result: Customer | I1: Result: Sales Staff | J1: Result: Technical Staff | K1: Result: Branch Manager | L1: Notes
A2: admin/dashboard.html | B2: Sent to login | C2: Sent to shop home | D2: "No access" alert, then POS | E2: Opens | F2: Opens | G2: Not run | H2: Not run | I2: Not run | J2: Not run | K2: Not run
A3: admin/pos.html | B3: Sent to login | C3: Sent to shop home | D3: Opens | E3: Opens | F3: Opens | G3: Not run | H3: Not run | I3: Not run | J3: Not run | K3: Not run
A4: admin/products.html | B4: Sent to login | C4: Sent to shop home | D4: Opens (view-only) | E4: Opens | F4: Opens | G4: Not run | H4: Not run | I4: Not run | J4: Not run | K4: Not run
A5: admin/online-orders.html | B5: Sent to login | C5: Sent to shop home | D5: "No access" alert, then POS | E5: Opens | F5: Opens | G5: Not run | H5: Not run | I5: Not run | J5: Not run | K5: Not run
A6: admin/inventory.html | B6: Sent to login | C6: Sent to shop home | D6: "No access" alert, then POS | E6: Opens | F6: Opens | G6: Not run | H6: Not run | I6: Not run | J6: Not run | K6: Not run
A7: admin/suppliers.html | B7: Sent to login | C7: Sent to shop home | D7: "No access" alert, then POS | E7: Opens | F7: Opens | G7: Not run | H7: Not run | I7: Not run | J7: Not run | K7: Not run
A8: admin/customer-accounts.html | B8: Sent to login | C8: Sent to shop home | D8: "No access" alert, then POS | E8: Opens | F8: Opens | G8: Not run | H8: Not run | I8: Not run | J8: Not run | K8: Not run
A9: admin/wholesale-accounts.html | B9: Sent to login | C9: Sent to shop home | D9: "No access" alert, then POS | E9: Opens | F9: Opens | G9: Not run | H9: Not run | I9: Not run | J9: Not run | K9: Not run
A10: admin/audit-log.html | B10: Sent to login | C10: Sent to shop home | D10: "No access" alert, then POS | E10: Opens | F10: Opens | G10: Not run | H10: Not run | I10: Not run | J10: Not run | K10: Not run
A11: admin/notifications.html | B11: Sent to login | C11: Sent to shop home | D11: "No access" alert, then POS | E11: Opens | F11: Opens | G11: Not run | H11: Not run | I11: Not run | J11: Not run | K11: Not run
A12: admin/live-chat.html | B12: Sent to login | C12: Sent to shop home | D12: "No access" alert, then POS | E12: Opens | F12: Opens | G12: Not run | H12: Not run | I12: Not run | J12: Not run | K12: Not run
A13: admin/reports.html | B13: Sent to login | C13: Sent to shop home | D13: "No access" alert, then POS | E13: Opens | F13: Opens | G13: Not run | H13: Not run | I13: Not run | J13: Not run | K13: Not run
... A29: shop/account-settings.html | B29: Asks to log in | C29: Opens | D29: As designed (staff are not customers) | E29: As designed | F29: As designed | G29: Not run | H29: Not run | I29: Not run | J29: Not run | K29: Not run
A31: Clear Test Data also switches itself off on 2026-11-15 (page refused for everyone after that).
